Workbook

Sheet Сводка
A1: Operator AI — тест-кейсы ручного тестирования
A2: Как пользоваться: открой лист модуля, выполни шаги кейса на тестовом стенде, запиши «Фактический результат» и поставь «Статус» из выпадающего списка. Сводка ниже пересчитается сама.
A3: Все проверки — только на тестовом стенде (staging). Учётные данные и токены — в .env, в этот файл их не вписываем. Названия кнопок даны по-русски, в скобках — узбекский вариант интерфейса. Колонка «Способ проверки»: UI — через браузер, API — запросом (curl/Postman, команда дана в шагах), UI+API — комбинированно. {STAGE_API_URL} в командах замени на адрес бэкенда тестового стенда из .env.
A5: Модуль | B5: Кейсов | C5: Passed | D5: Failed | E5: Blocked | F5: Not Run | G5: % пройдено
A6: 01 Авторизация | B6: 20 | C6: =COUNTIF('01 Авторизация'!$K$2:$K$21,"Passed") | D6: =COUNTIF('01 Авторизация'!$K$2:$K$21,"Failed") | E6: =COUNTIF('01 Авторизация'!$K$2:$K$21,"Blocked") | F6: =COUNTIF('01 Авторизация'!$K$2:$K$21,"Not Run") | G6: =IF(B6=0,0,C6/B6)
A7: 02 Права и изоляция | B7: 23 | C7: =COUNTIF('02 Права и изоляция'!$K$2:$K$24,"Passed") | D7: =COUNTIF('02 Права и изоляция'!$K$2:$K$24,"Failed") | E7: =COUNTIF('02 Права и изоляция'!$K$2:$K$24,"Blocked") | F7: =COUNTIF('02 Права и изоляция'!$K$2:$K$24,"Not Run") | G7: =IF(B7=0,0,C7/B7)
A8: 03 Пользователи | B8: 21 | C8: =COUNTIF('03 Пользователи'!$K$2:$K$22,"Passed") | D8: =COUNTIF('03 Пользователи'!$K$2:$K$22,"Failed") | E8: =COUNTIF('03 Пользователи'!$K$2:$K$22,"Blocked") | F8: =COUNTIF('03 Пользователи'!$K$2:$K$22,"Not Run") | G8: =IF(B8=0,0,C8/B8)
A9: 04 Лиды и статусы | B9: 27 | C9: =COUNTIF('04 Лиды и статусы'!$K$2:$K$28,"Passed") | D9: =COUNTIF('04 Лиды и статусы'!$K$2:$K$28,"Failed") | E9: =COUNTIF('04 Лиды и статусы'!$K$2:$K$28,"Blocked") | F9: =COUNTIF('04 Лиды и статусы'!$K$2:$K$28,"Not Run") | G9: =IF(B9=0,0,C9/B9)
A10: 05 Очередь обзвона | B10: 23 | C10: =COUNTIF('05 Очередь обзвона'!$K$2:$K$24,"Passed") | D10: =COUNTIF('05 Очередь обзвона'!$K$2:$K$24,"Failed") | E10: =COUNTIF('05 Очередь обзвона'!$K$2:$K$24,"Blocked") | F10: =COUNTIF('05 Очередь обзвона'!$K$2:$K$24,"Not Run") | G10: =IF(B10=0,0,C10/B10)
A11: 06 Звонок (цикл) | B11: 27 | C11: =COUNTIF('06 Звонок (цикл)'!$K$2:$K$28,"Passed") | D11: =COUNTIF('06 Звонок (цикл)'!$K$2:$K$28,"Failed") | E11: =COUNTIF('06 Звонок (цикл)'!$K$2:$K$28,"Blocked") | F11: =COUNTIF('06 Звонок (цикл)'!$K$2:$K$28,"Not Run") | G11: =IF(B11=0,0,C11/B11)
A12: 07 AI-анализ | B12: 24 | C12: =COUNTIF('07 AI-анализ'!$K$2:$K$25,"Passed") | D12: =COUNTIF('07 AI-анализ'!$K$2:$K$25,"Failed") | E12: =COUNTIF('07 AI-анализ'!$K$2:$K$25,"Blocked") | F12: =COUNTIF('07 AI-анализ'!$K$2:$K$25,"Not Run") | G12: =IF(B12=0,0,C12/B12)
A13: 08 AmoCRM | B13: 34 | C13: =COUNTIF('08 AmoCRM'!$K$2:$K$35,"Passed") | D13: =COUNTIF('08 AmoCRM'!$K$2:$K$35,"Failed") | E13: =COUNTIF('08 AmoCRM'!$K$2:$K$35,"Blocked") | F13: =COUNTIF('08 AmoCRM'!$K$2:$K$35,"Not Run") | G13: =IF(B13=0,0,C13/B13)
A14: 09 OnlinePBX | B14: 27 | C14: =COUNTIF('09 OnlinePBX'!$K$2:$K$28,"Passed") | D14: =COUNTIF('09 OnlinePBX'!$K$2:$K$28,"Failed") | E14: =COUNTIF('09 OnlinePBX'!$K$2:$K$28,"Blocked") | F14: =COUNTIF('09 OnlinePBX'!$K$2:$K$28,"Not Run") | G14: =IF(B14=0,0,C14/B14)
A15: 10 Тарифы | B15: 26 | C15: =COUNTIF('10 Тарифы'!$K$2:$K$27,"Passed") | D15: =COUNTIF('10 Тарифы'!$K$2:$K$27,"Failed") | E15: =COUNTIF('10 Тарифы'!$K$2:$K$27,"Blocked") | F15: =COUNTIF('10 Тарифы'!$K$2:$K$27,"Not Run") | G15: =IF(B15=0,0,C15/B15)
A16: 11 Локализация | B16: 20 | C16: =COUNTIF('11 Локализация'!$K$2:$K$21,"Passed") | D16: =COUNTIF('11 Локализация'!$K$2:$K$21,"Failed") | E16: =COUNTIF('11 Локализация'!$K$2:$K$21,"Blocked") | F16: =COUNTIF('11 Локализация'!$K$2:$K$21,"Not Run") | G16: =IF(B16=0,0,C16/B16)
A17: 12 Смены и посещаемость | B17: 35 | C17: =COUNTIF('12 Смены и посещаемость'!$K$2:$K$36,"Passed") | D17: =COUNTIF('12 Смены и посещаемость'!$K$2:$K$36,"Failed") | E17: =COUNTIF('12 Смены и посещаемость'!$K$2:$K$36,"Blocked") | F17: =COUNTIF('12 Смены и посещаемость'!$K$2:$K$36,"Not Run") | G17: =IF(B17=0,0,C17/B17)
A18: 13 Лендинг и сквозное | B18: 30 | C18: =COUNTIF('13 Лендинг и сквозное'!$K$2:$K$31,"Passed") | D18: =COUNTIF('13 Лендинг и сквозное'!$K$2:$K$31,"Failed") | E18: =COUNTIF('13 Лендинг и сквозное'!$K$2:$K$31,"Blocked") | F18: =COUNTIF('13 Лендинг и сквозное'!$K$2:$K$31,"Not Run") | G18: =IF(B18=0,0,C18/B18)
A19: ИТОГО (без отложенных) | B19: =SUM(B6:B18) | C19: =SUM(C6:C18) | D19: =SUM(D6:D18) | E19: =SUM(E6:E18) | F19: =SUM(F6:F18) | G19: =IF(B19=0,0,C19/B19)
A21: Вне общей статистики (ждут релиза):
A22: 14 Отложенные до релиза | B22: 13 | C22: =COUNTIF('14 Отложенные до релиза'!$K$2:$K$14,"Passed") | D22: =COUNTIF('14 Отложенные до релиза'!$K$2:$K$14,"Failed") | E22: =COUNTIF('14 Отложенные до релиза'!$K$2:$K$14,"Blocked") | F22: =COUNTIF('14 Отложенные до релиза'!$K$2:$K$14,"Not Run") | G22: —
A25: Сверка рисков R-1…R-10 → тест-кейсы
A26: Риск | B26: Что проверяем | E26: Покрывающие кейсы
A27: R-1 | B27: Утечка данных между клиентами | E27: TC-032–TC-038, TC-199, TC-215, TC-292, TC-349
A28: R-2 | B28: Дыры в правах доступа | E28: TC-021–TC-043, TC-208, TC-241, TC-327, TC-349
A29: R-3 | B29: Потеря данных при синхронизации с AmoCRM | E29: TC-181, TC-183–TC-197, TC-331
A30: R-4 | B30: Неверные данные от AI | E30: TC-152–TC-164
A31: R-5 | B31: Дефолтные учётные записи | E31: TC-008, TC-011, TC-337
A32: R-6 | B32: Молчаливая потеря звонков в AI-обработке | E32: TC-146–TC-151, TC-348
A33: R-7 | B33: Двойной обзвон одного лида | E33: TC-100–TC-104, TC-123, TC-139
A34: R-8 | B34: Автосинхронизация без подтверждения | E34: TC-131, TC-133–TC-135, TC-141
A35: R-9 | B35: Неверный жизненный счётчик попыток | E35: TC-084–TC-089, TC-334
A36: R-10 | B36: Тестовый фронт обращается к production | E36: TC-335, TC-336

Sheet 01 Авторизация
A1: ID | B1: Краткое описание | C1: Полное описание | D1: Предусловия | E1: Шаги | F1: Приоритет | G1: Тип | H1: Способ проверки | I1: Ожидаемый результат | J1: Фактический результат | K1: Статус | L1: Автоматизация
A2: TC-001 | B2: Вход супер-админа с верными логином и паролем | C2: Проверяем, что сотрудник компании-владельца (супер-админ) может войти в систему и попадает на свой стартовый экран — список РОПов. Вход — «ворота» во всю систему, поэтому кейс критичный. | D2: Есть учётная запись супер-админа (логин и пароль — в .env, в кейсе не указываются). Открыт браузер, никто не залогинен. | E2: 1. Открой страницу входа (адрес стенда + /auth/jwt/sign-in). 2. В поле «Логин» (uz: Login) введи логин супер-админа. 3. В поле «Пароль» (uz: Parol) введи его пароль. 4. Нажми кнопку «Войти» (uz: Kirish). | F2: Critical | G2: Позитивный | H2: UI | I2: Вход выполнен. Открывается раздел «РОПы» (адрес /dashboard/rop) — таблица компаний РОП. В меню слева видны разделы «РОПы», «Лиды», «Тарифы». | K2: Not Run | L2: —
A3: TC-002 | B3: Вход РОП с верными логином и паролем | C3: Проверяем вход руководителя отдела продаж (РОП) и что система приводит его на его стартовый экран — «Правила». | D3: Есть учётная запись РОП. Никто не залогинен. | E3: 1. Открой страницу входа. 2. Введи логин и пароль РОП. 3. Нажми «Войти» (uz: Kirish). | F3: Critical | G3: Позитивный | H3: UI | I3: Вход выполнен. Открывается раздел «Правила» (адрес /dashboard/dynamic-form). В меню слева: «Правила», «Операторы», «Настройка очереди», «Критерии», «Посещаемость». | K3: Not Run | L3: —
A4: TC-003 | B4: Вход оператора с верными логином и паролем | C4: Проверяем вход оператора и его стартовый экран. ВНИМАНИЕ: по коду фронтенда оператора после входа ведут на «Звонки» (/dashboard/calls), а не на «Рабочий стол», как написано в старой документации. Код — источник правды. | D4: Есть учётная запись оператора. Никто не залогинен. | E4: 1. Открой страницу входа. 2. Введи логин и пароль оператора. 3. Нажми «Войти» (uz: Kirish). | F4: Critical | G4: Позитивный | H4: UI | I4: Вход выполнен. Открывается раздел «Звонки» (адрес /dashboard/calls) — таблица лидов. В меню слева: «Рабочий стол», «Режим звонков», «Звонки», «Рабочее время». | K4: Not Run | L4: —
A5: TC-004 | B5: Вход с неверным паролем не пускает в систему | C5: Проверяем, что с неправильным паролем войти нельзя и человеку показывается понятное сообщение об ошибке. | D5: Есть любая действующая учётная запись. Никто не залогинен. | E5: 1. Открой страницу входа. 2. Введи существующий логин. 3. Введи заведомо неверный пароль (например, правильный + лишняя буква). 4. Нажми «Войти». | F5: Critical | G5: Негативный | H5: UI | I5: Вход НЕ выполнен. Над формой появляется красная плашка с сообщением об ошибке. Пользователь остаётся на странице входа. Пароль в поле не раскрывается. | K5: Not Run | L5: —
A6: TC-005 | B6: Вход с несуществующим логином | C6: Проверяем реакцию на логин, которого нет в системе. Сообщение не должно подсказывать злоумышленнику, что именно неверно — логин или пароль. | D6: Никто не залогинен. | E6: 1. Открой страницу входа. 2. Введи выдуманный логин, например «net-takogo-usera-123». 3. Введи любой пароль от 6 символов. 4. Нажми «Войти». | F6: High | G6: Негативный | H6: UI | I6: Вход НЕ выполнен, показано сообщение об ошибке. Формулировка ошибки одинаковая для случаев «нет такого логина» и «неверный пароль» (не выдаёт, какие логины существуют). | K6: Not Run | L6: —
A7: TC-006 | B7: Пустые поля — форма подсказывает, что заполнить | C7: Проверяем подсказки формы при попытке войти, ничего не заполнив. Запрос на сервер при этом уходить не должен. | D7: Никто не залогинен. | E7: 1. Открой страницу входа. 2. Ничего не вводи в поля. 3. Нажми «Войти». | F7: Medium | G7: Негативный | H7: UI | I7: Под полями появляются подсказки: «Введите логин!» (uz: Loginni kiriting!) и «Введите пароль!» (uz: Parolni kiriting!). Вход не выполняется. | K7: Not Run | L7: —
A8: TC-007 | B8: Пароль короче 6 символов не отправляется | C8: Граничная проверка минимальной длины пароля на форме входа: 5 символов — ошибка, 6 символов — форма отправляет запрос (сервер уже сам решает, верный ли пароль). | D8: Никто не залогинен. | E8: 1. Открой страницу входа. 2. Введи любой логин. 3. Введи пароль из 5 символов (например, «12345»). Нажми «Войти». 4. Теперь введи пароль из 6 символов (например, «123456»). Нажми «Войти». | F8: Medium | G8: Граничный | H8: UI | I8: Шаг 3: под полем подсказка «Пароль должен содержать не менее 6 символов!», запрос на сервер не уходит. Шаг 4: подсказки нет, форма отправляется (дальше — обычная ошибка «неверный пароль», это нормально). | K8: Not Run | L8: —
A9: TC-008 | B9: Поля входа не предзаполнены логином и паролем | C9: Проверка безопасности (риск R-5, дефект Р-17). Раньше в форме входа были захардкожены учётные данные супер-админа — любой мог войти в один клик. По коду от 25.07 это исправлено. Подтверждаем на стенде. | D9: Никто не залогинен. Открой новое приватное окно браузера (Ctrl+Shift+N), чтобы исключить автозаполнение самим браузером. | E9: 1. Открой страницу входа в приватном окне. 2. Посмотри на поля «Логин» и «Пароль», ничего не вводя. | F9: High | G9: Негативный | H9: UI | I9: Оба поля ПУСТЫЕ. Внутри — только серые подсказки-плейсхолдеры «логин» и «6+ символов». Никаких заранее подставленных логина и пароля нет. | K9: Not Run | L9: —
A10: TC-009 | B10: Кнопка-глазок показывает и скрывает пароль | C10: Удобство: оператор должен иметь возможность проверить, что набрал, прежде чем нажать «Войти». | D10: Никто не залогинен. | E10: 1. Открой страницу входа. 2. Введи в поле «Пароль» любой текст. 3. Нажми значок глаза в правом краю поля. 4. Нажми значок ещё раз. | F10: Low | G10: Позитивный | H10: UI | I10: После первого нажатия пароль виден обычным текстом, после второго — снова скрыт точками. | K10: Not Run | L10: —
A11: TC-010 | B11: Выход из системы | C11: Проверяем, что «Выйти» действительно завершает сессию: вернуться в кабинет кнопкой «Назад» браузера нельзя. | D11: Выполнен вход под любой ролью. | E11: 1. Нажми на свой аватар/имя в правом верхнем углу. 2. В открывшемся меню нажми «Выйти» (uz: Chiqish). 3. После возврата на страницу входа нажми кнопку «Назад» в браузере. 4. Обнови страницу (F5). | F11: High | G11: Позитивный | H11: UI | I11: После шага 2 открывается страница входа. Шаги 3–4: в кабинет вернуться нельзя — снова показывается страница входа, данные разделов не отображаются. | K11: Not Run | L11: —
A12: TC-011 | B12: Защита от перебора: много неверных попыток подряд | C12: На вход стоит ограничение частоты запросов (по умолчанию 5 попыток в минуту с одного адреса). Проверяем, что после лишних попыток система временно блокирует вход, а через минуту снова пускает. | D12: Есть действующая учётная запись. Никто не залогинен. | E12: 1. Открой страницу входа. 2. Введи существующий логин и неверный пароль. Нажми «Войти». 3. Повтори то же самое ещё 5 раз подряд, не делая пауз (всего 6 попыток). 4. Подожди чуть больше минуты и попробуй войти с ВЕРНЫМ паролем. | F12: Medium | G12: Негативный | H12: UI | I12: На 6-й попытке появляется ошибка об ограничении (слишком много запросов) — даже если бы пароль был верным. После паузы в минуту вход с верным паролем работает. | K12: Not Run | L12: —
A13: TC-012 | B13: Деактивированный пользователь не может войти | C13: РОП отключает оператора (уволился) — вход для него должен закрыться, но его данные (звонки, история) должны остаться в системе. | D13: Вход под РОП. У РОП есть оператор, под которым можно безопасно экспериментировать (тестовый). | E13: 1. Открой раздел «Операторы». 2. Найди строку тестового оператора, открой меню действий (⋮). 3. Нажми «Деактивировать» (uz: Deaktivatsiya). 4. Убедись, что появилось уведомление «Деактивировано» и статус в таблице сменился на «Неактивен». 5. Выйди из аккаунта РОП. Попробуй войти под этим оператором с его верным паролем. 6. Вернись под РОП и проверь, что история звонков оператора по-прежнему видна. | F13: Critical | G13: Негативный | H13: UI | I13: Шаг 5: вход НЕ выполняется, показано сообщение об ошибке. Шаг 6: данные оператора не пропали. После теста верни оператора кнопкой «Активировать». | K13: Not Run | L13: —
... A21: TC-020 | B21: Двойное нажатие «Войти» не ломает вход | C21: Нетерпеливый пользователь может кликнуть кнопку дважды. Это не должно приводить к ошибке или двойному входу. | D21: Есть действующая учётная запись. Никто не залогинен. | E21: 1. Открой страницу входа, введи верные логин и пароль. 2. Быстро нажми кнопку «Войти» два раза подряд. | F21: Low | G21: Негативный | H21: UI | I21: Выполняется один обычный вход. Во время обработки кнопка блокируется и показывает «Вход...» (uz: Kirilmoqda...). Ошибок на экране нет. | K21: Not Run | L21: —

Sheet 02 Права и изоляция
A1: ID | B1: Краткое описание | C1: Полное описание | D1: Предусловия | E1: Шаги | F1: Приоритет | G1: Тип | H1: Способ проверки | I1: Ожидаемый результат | J1: Фактический результат | K1: Статус | L1: Автоматизация
A2: TC-021 | B2: Меню супер-админа содержит только его разделы | C2: У каждой роли своё меню. Супер-админ управляет клиентами и тарифами, но НЕ должен видеть рабочие разделы РОП и оператора. Иерархии ролей в системе нет — доступ задан явными списками (риск R-2). | D2: Вход под супер-админом. | E2: 1. Посмотри на меню слева. 2. Выпиши все пункты меню в фактический результат. | F2: High | G2: Позитивный | H2: UI | I2: В меню есть: «РОПы», «Лиды», «Тарифы». В меню НЕТ: «Правила», «Настройка очереди», «Критерии», «Посещаемость», «Режим звонков», «Рабочее время», «Рабочий стол». | K2: Not Run | L2: —
A3: TC-022 | B3: Меню РОП содержит только его разделы | C3: РОП настраивает правила и управляет операторами, но не видит разделы супер-админа (клиенты, тарифы) и рабочие экраны оператора. | D3: Вход под РОП. | E3: 1. Посмотри на меню слева. 2. Выпиши все пункты меню в фактический результат. | F3: High | G3: Позитивный | H3: UI | I3: В меню есть: «Правила», «Операторы», «Настройка очереди», «Критерии», «Посещаемость». В меню НЕТ: «РОПы», «Лиды», «Тарифы», «Режим звонков», «Рабочий стол», «Рабочее время». | K3: Not Run | L3: —
A4: TC-023 | B4: Меню оператора содержит только его разделы | C4: Оператор звонит и подтверждает результаты. Управленческих разделов у него быть не должно. | D4: Вход под оператором. | E4: 1. Посмотри на меню слева. 2. Выпиши все пункты меню в фактический результат. | F4: High | G4: Позитивный | H4: UI | I4: В меню есть: «Рабочий стол», «Режим звонков», «Звонки», «Рабочее время». В меню НЕТ: «РОПы», «Лиды», «Тарифы», «Правила», «Операторы», «Настройка очереди», «Критерии», «Посещаемость». | K4: Not Run | L4: —
A5: TC-024 | B5: Оператор не открывает список РОПов по прямой ссылке | C5: Спрятать пункт меню — мало: раздел можно открыть, введя адрес руками. Проверяем защиту самого экрана (риск R-2). | D5: Вход под оператором. | E5: 1. В адресной строке браузера введи адрес стенда + /dashboard/rop и нажми Enter. | F5: Critical | G5: Негативный | H5: UI | I5: Список РОПов НЕ показывается. Появляется заглушка «нет доступа» (или редирект на разрешённый раздел). Никакие данные таблицы не видны даже на долю секунды. | K5: Not Run | L5: —
A6: TC-025 | B6: Оператор не открывает «Тарифы» и «Лиды» по прямой ссылке | C6: Продолжение проверки прямых ссылок для оператора: экраны супер-админа «Тарифы» (цены) и «Лиды» (заявки с сайта) должны быть закрыты. | D6: Вход под оператором. | E6: 1. Введи в адресной строке адрес стенда + /dashboard/plans. Посмотри результат. 2. Введи адрес стенда + /dashboard/leads. Посмотри результат. | F6: Critical | G6: Негативный | H6: UI | I6: Оба раздела НЕ открываются — заглушка «нет доступа», данных не видно. | K6: Not Run | L6: —
A7: TC-026 | B7: РОП не открывает разделы супер-админа по прямой ссылке | C7: РОП — это клиент компании. Список всех клиентов, заявки с сайта и управление тарифами — коммерческая информация владельца платформы. | D7: Вход под РОП. | E7: 1. Введи в адресной строке адрес стенда + /dashboard/rop. 2. Затем /dashboard/leads. 3. Затем /dashboard/plans. | F7: Critical | G7: Негативный | H7: UI | I7: Ни один из трёх разделов не открывается — везде заглушка «нет доступа», данные не показываются. | K7: Not Run | L7: —
A8: TC-027 | B8: РОП не открывает рабочие экраны оператора | C8: «Режим звонков» и «Рабочее время» — личные рабочие экраны оператора. РОП управляет, но не звонит; его вход в режим обзвона мог бы захватить лида и сломать очередь. | D8: Вход под РОП. | E8: 1. Введи в адресной строке адрес стенда + /dashboard/calling. 2. Затем /dashboard/work. 3. Затем /dashboard/home. | F8: High | G8: Негативный | H8: UI | I8: Ни один экран не открывается — заглушка «нет доступа». Лид из очереди НЕ захвачен (в /dashboard/calling даже счётчик очереди не должен отработать). | K8: Not Run | L8: —
A9: TC-028 | B9: Супер-админ не открывает экраны РОП | C9: Важная особенность системы: супер-админ НЕ «выше всех» — у него нет доступа к настройкам РОП. Проверяем, что список доступа нигде не расширен по ошибке. | D9: Вход под супер-админом. | E9: 1. Введи в адресной строке адрес стенда + /dashboard/dynamic-form (Правила). 2. Затем /dashboard/mezonlar (Критерии). 3. Затем /dashboard/operator-pipelines (Настройка очереди). 4. Затем /dashboard/attendance (Посещаемость). | F9: High | G9: Негативный | H9: UI | I9: Ни один из четырёх разделов не открывается — везде заглушка «нет доступа». | K9: Not Run | L9: —
A10: TC-029 | B10: Супер-админ не открывает рабочие экраны оператора | C10: Аналогично TC-028 — но для экранов оператора: режим обзвона, смена, рабочий стол, таблица лидов. | D10: Вход под супер-админом. | E10: 1. Введи в адресной строке адрес стенда + /dashboard/calling. 2. Затем /dashboard/calls (таблица лидов оператора). 3. Затем /dashboard/work. 4. Затем /dashboard/home. | F10: High | G10: Негативный | H10: UI | I10: Ни один экран не открывается — заглушка «нет доступа». Лид из очереди не захвачен. | K10: Not Run | L10: —
A11: TC-030 | B11: Незалогиненный гость всегда попадает на страницу входа | C11: Любой внутренний адрес системы без входа должен вести на форму логина, а не показывать данные. | D11: Никто не залогинен (новое приватное окно браузера). | E11: 1. Введи в адресной строке адрес стенда + /dashboard/calls. 2. Затем /dashboard/rop. 3. Затем /dashboard/mezonlar. | F11: Critical | G11: Негативный | H11: UI | I11: Во всех трёх случаях открывается страница входа. Никакие данные разделов не мелькают до редиректа. | K11: Not Run | L11: —
A12: TC-031 | B12: Супер-админ не может править операторов чужого РОП | C12: По требованию доступ супер-админа к операторам РОП — «только просмотр». Но таблица операторов у него та же, что у РОП, и кнопки действий в ней технически есть (находка из анализа кода, риск R-2). Проверяем, что сервер отклоняет изменения. | D12: Вход под супер-админом. У тестового РОП есть тестовый оператор. | E12: 1. Открой «РОПы», нажми на строку тестового РОП — откроется его карточка со списком операторов. 2. Попробуй найти у оператора действия «Редактировать» / «Деактивировать» / «Сбросить пароль». 3. Если действия доступны — попробуй изменить у оператора имя и сохранить. | F12: High | G12: Негативный | H12: UI | I12: Идеально: действий редактирования нет вообще (только просмотр). Допустимо: действия видны, но сервер отвечает отказом и данные не меняются. Если изменение ПРОШЛО — это дефект прав (R-2), фиксируй как баг. | K12: Not Run | L12: —
A13: TC-032 | B13: РОП-А не видит операторов РОП-Б | C13: Главная проверка изоляции клиентов (риск R-1 — критический). Два разных клиента платформы не должны видеть данные друг друга. | D13: На стенде есть два РОП: РОП-А и РОП-Б, у каждого хотя бы один оператор. Логины обоих известны QA. | E13: 1. Войди под РОП-А, открой «Операторы». 2. Выпиши список операторов. 3. Выйди, войди под РОП-Б, открой «Операторы». 4. Сравни списки. | F13: Critical | G13: Негативный | H13: UI | I13: Каждый РОП видит ТОЛЬКО своих операторов. Ни одного пересечения между списками нет. | K13: Not Run | L13: —
... A24: TC-043 | B24: Смена роли требует нового входа: сессии не смешиваются | C24: Проверяем, что после выхода из-под одной роли и входа под другой права применяются заново — меню и доступы соответствуют НОВОЙ роли, ничего не «прилипло» от предыдущей. | D24: Известны учётные записи РОП и оператора одной компании. | E24: 1. Войди под РОП. Убедись, что видишь меню РОП (см. TC-022). 2. Выйди. Войди под оператором в том же браузере. 3. Посмотри меню и попробуй открыть /dashboard/mezonlar по прямой ссылке. | F24: High | G24: Негативный | H24: UI | I24: После входа под оператором меню — операторское (см. TC-023), а «Критерии» по прямой ссылке НЕ открываются, хотя минуту назад под РОП открывались. | K24: Not Run | L24: —

Sheet 03 Пользователи
A1: ID | B1: Краткое описание | C1: Полное описание | D1: Предусловия | E1: Шаги | F1: Приоритет | G1: Тип | H1: Способ проверки | I1: Ожидаемый результат | J1: Фактический результат | K1: Статус | L1: Автоматизация
A2: TC-044 | B2: Супер-админ создаёт нового РОП | C2: Проверяем основной путь создания компании РОП. РОП — руководитель отдела продаж, который после создания получает собственную компанию и сможет добавлять операторов. | D2: Работа ведётся только на staging. Выполнен вход под супер-админом. Подготовлены уникальные логин, телефон и название тестовой компании. | E2: 1. В меню слева открой раздел «РОПы». 2. Нажми кнопку «Новый РОП». 3. Заполни поля «Имя», «Фамилия», «Телефон», «Пароль», «Имя пользователя (логин)» и «Название компании». 4. В поле «Тариф» выбери любой тестовый тариф. 5. Нажми кнопку «Создать». 6. Найди новую компанию в таблице «Компании РОП». | F2: Critical | G2: Позитивный | H2: UI | I2: Появляется сообщение «Пользователь создан». В таблице есть ровно одна новая строка с указанной компанией и Ф.И.О.; роль — «РОП», статус — «Активен». Созданный РОП может войти со своими логином и паролем. | K2: Not Run | L2: —
A3: TC-045 | B3: Создание РОП с пустыми обязательными полями запрещено | C3: Проверяем, что пустая карточка не сохраняется. Это защищает список пользователей от записей без имени, контакта, логина или компании. | D3: Выполнен вход под супер-админом, открыт раздел «РОПы». | E3: 1. Нажми «Новый РОП». 2. Ничего не вводи и по очереди нажми в каждое поле, затем щёлкни вне поля. 3. Посмотри на подсказки под полями. 4. Проверь состояние кнопки «Создать». | F3: High | G3: Негативный | H3: UI | I3: Под пустыми полями показаны понятные сообщения: «Имя обязательно», «Фамилия обязательна», «Телефон обязателен», «Имя пользователя обязательно», «Название компании обязательно» и требование к паролю. Кнопка «Создать» неактивна, пользователь не появляется. | K3: Not Run | L3: —
A4: TC-046 | B4: Телефон РОП принимает только номер Узбекистана | C4: Регрессия BUG-004: раньше поле телефона принимало буквы и любой текст. Проверяем формат +998 и девять цифр абонента. | D4: Выполнен вход под супер-админом, открыта форма «Создать РОП». Остальные поля заполнены корректными уникальными значениями. | E4: 1. В поле «Телефон» введи буквы, например «абвгд». 2. Щёлкни вне поля и прочитай сообщение. 3. Замени значение на слишком короткий номер «+998 90 123». 4. Щёлкни вне поля и снова проверь сообщение. 5. Введи корректный тестовый номер в формате «+998 90 123 45 67». | F4: High | G4: Негативный | H4: UI | I4: Для букв и короткого номера показано «Неверный номер телефона (+998 XX XXX XX XX)», создание недоступно. После корректного номера ошибка исчезает. | K4: Not Run | L4: —
A5: TC-047 | B5: Одинаковый телефон нельзя выдать двум РОП | C5: Регрессия BUG-007. Система сравнивает только цифры, поэтому номер с пробелами и тот же номер без пробелов должны считаться одним номером. | D5: На staging уже есть тестовый РОП с телефоном «+998 90 123 45 67». Выполнен вход под супер-админом. | E5: 1. Нажми «Новый РОП». 2. Заполни все поля новыми значениями, но в «Телефон» введи «998901234567» без пробелов. 3. Нажми «Создать». 4. Проверь сообщение и таблицу «Компании РОП». | F5: High | G5: Негативный | H5: UI | I5: Появляется понятная ошибка о том, что телефон уже используется. Второй РОП не создан; в таблице остаётся только один пользователь с этим номером. | K5: Not Run | L5: —
A6: TC-048 | B6: Одинаковый логин нельзя выдать двум пользователям | C6: Логин — уникальное имя для входа. Если два человека получат одинаковый логин, система не сможет однозначно определить, кто входит. | D6: На staging существует тестовый пользователь с известным логином. Выполнен вход под супер-админом. | E6: 1. Открой форму «Новый РОП». 2. Заполни все поля уникальными данными, кроме поля «Имя пользователя (логин)». 3. Введи логин уже существующего пользователя. 4. Нажми «Создать». | F6: High | G6: Негативный | H6: UI | I6: Показана ошибка о занятом имени пользователя. Второй пользователь с тем же логином не создаётся. | K6: Not Run | L6: —
A7: TC-049 | B7: Супер-админ редактирует данные РОП | C7: Проверяем изменение контактных данных и названия компании без случайной смены роли или потери подключений. | D7: Есть отдельный тестовый РОП. Выполнен вход под супер-админом, открыт раздел «РОПы». | E7: 1. В строке тестового РОП нажми значок редактирования с подсказкой «Редактировать». 2. В окне «Редактировать пользователя» измени «Имя», «Фамилия», «Телефон» и «Название компании». 3. Проверь, что поле «Роль» недоступно для ввода. 4. Нажми «Сохранить». 5. Обнови страницу браузера и снова найди этого РОП. | F7: High | G7: Позитивный | H7: UI | I7: Появляется «Пользователь сохранён». После обновления видны новые данные; роль осталась «РОП», пользователь не продублировался, его интеграции не исчезли. | K7: Not Run | L7: —
A8: TC-050 | B8: Деактивация РОП действует сразу и сохраняет данные | C8: Проверяем исправление BUG-006. Деактивация похожа на временную блокировку пропуска: данные остаются, но пользоваться системой больше нельзя с первого следующего действия. | D8: Есть отдельный тестовый РОП. В первом браузере выполнен вход под супер-админом, во втором — под этим РОП; у РОП открыта любая рабочая страница. | E8: 1. В первом браузере в строке РОП нажми действие «Деактивировать». 2. Во втором браузере обнови страницу или открой любой раздел. 3. Проверь, что рабочие данные больше не открываются и показана страница входа либо отказ 401. 4. В первом браузере проверь статус РОП в таблице. 5. Нажми «Активировать». 6. Войди под РОП снова и проверь его компанию и список операторов. | F8: Critical | G8: Позитивный | H8: UI | I8: После деактивации следующий запрос РОП сразу отклонён; ждать 15 минут не требуется. В таблице статус «Неактивен». После активации вход снова работает, компания, операторы и настройки сохранились. | K8: Not Run | L8: —
A9: TC-051 | B9: Удаление тестового РОП требует подтверждения | C9: Удаление трудно отменить, поэтому сначала проверяем отмену, затем подтверждаем удаление только для специально созданной тестовой компании. | D9: На staging создан отдельный РОП без нужных данных и интеграций. Выполнен вход под супер-админом. | E9: 1. В строке тестового РОП нажми значок удаления. 2. В окне «Удалить пользователя» нажми «Отмена». 3. Убедись, что РОП остался в таблице. 4. Снова нажми значок удаления и в окне подтверждения нажми «Удалить». 5. Обнови страницу и найди РОП по названию компании. 6. Попробуй войти под удалённым РОП. | F9: High | G9: Позитивный | H9: UI | I9: После «Отмена» ничего не меняется. После подтверждения появляется «Пользователь удалён», строка исчезает, вход удалённой учётной записью невозможен. | K9: Not Run | L9: —
A10: TC-052 | B10: РОП создаёт оператора с доступным внутренним номером | C10: Внутренний номер — короткий номер сотрудника в OnlinePBX. Он выбирается из списка, чтобы звонки и записи привязывались к правильному оператору. | D10: Выполнен вход под РОП. Для его компании подключён OnlinePBX; в нём есть свободный включённый внутренний номер. Подготовлены уникальные логин и телефон. | E10: 1. В меню открой «Операторы». 2. Нажми «Новый оператор». 3. Заполни «Имя», «Фамилия», «Телефон», «Пароль» и «Имя пользователя». 4. В поле «PBX extension (внутренний номер)» выбери свободного сотрудника. 5. Введи положительную «Зарплату» и выбери «День зарплаты». 6. Нажми «Создать». 7. Найди оператора в таблице. | F10: Critical | G10: Позитивный | H10: UI | I10: Появляется «Пользователь создан». Оператор виден один раз, имеет статус «Активен» и выбранный внутренний номер. Он может войти в систему. | K10: Not Run | L10: —
A11: TC-053 | B11: Оператор без обязательных данных не создаётся | C11: Проверяем все обязательные поля формы оператора, включая телефонию и оплату труда. | D11: Выполнен вход под РОП, открыта форма «Создать оператора». | E11: 1. Оставь все поля пустыми. 2. По очереди нажми в каждое поле и затем щёлкни вне него. 3. Посмотри сообщения под полями «Имя», «Фамилия», «Телефон», «Пароль», «Имя пользователя», «PBX extension», «Зарплата» и «День зарплаты». 4. Проверь кнопку «Создать». | F11: High | G11: Негативный | H11: UI | I11: У каждого обязательного поля есть понятная подсказка. Кнопка «Создать» неактивна, пустой оператор в таблице не появляется. | K11: Not Run | L11: —
A12: TC-054 | B12: Занятый или выключенный внутренний номер выбрать нельзя | C12: Один внутренний номер не должен одновременно принадлежать двум операторам: иначе звонки и записи будут приписаны не тому человеку. | D12: OnlinePBX подключён. В списке есть один свободный номер, один уже назначенный и один выключенный номер. Выполнен вход под РОП. | E12: 1. Открой «Новый оператор». 2. Раскрой список «PBX extension (внутренний номер)». 3. Найди строку с пометкой «занят». 4. Попробуй выбрать занятую и выключенную строки. 5. Выбери свободный номер. | F12: High | G12: Негативный | H12: UI | I12: Занятый и выключенный номера видны, но недоступны для выбора. Свободный номер выбирается нормально. | K12: Not Run | L12: —
A13: TC-055 | B13: Без внутреннего номера оператор не создаётся при недоступном OnlinePBX | C13: Если список OnlinePBX загрузить нельзя, система показывает обычное текстовое поле. Даже в этом запасном режиме пустой внутренний номер запрещён. | D13: На staging временно отсутствует конфигурация OnlinePBX либо тестировщик по согласованию заблокировал запрос списка внутренних номеров. Выполнен вход под РОП. | E13: 1. Открой форму «Создать оператора». 2. Дождись, когда вместо списка появится поле «PBX extension (внутренний номер OnlinePBX, например 100)». 3. Заполни остальные поля, а это поле оставь пустым. 4. Нажми вне поля и проверь форму. | F13: Critical | G13: Негативный | H13: UI | I13: Показано «PBX extension обязателен», кнопка «Создать» неактивна. Оператор без внутреннего номера не появляется. | K13: Not Run | L13: —
... A22: TC-064 | B22: Потеря сети при создании пользователя не создаёт «призрак» | C22: Если связь пропала во время сохранения, интерфейс должен честно показать ошибку, а повторная попытка после восстановления не должна дать дубликат. | D22: Выполнен вход под супер-админом. Форма «Создать РОП» заполнена уникальными тестовыми данными. | E22: 1. В инструментах браузера включи режим Offline (без сети). 2. Нажми «Создать». 3. Проверь сообщение об ошибке и то, что форма не закрылась бесследно. 4. Верни сеть в режим Online. 5. Нажми «Создать» один раз и дождись результата. 6. Обнови таблицу и найди пользователя по логину. | F22: High | G22: Негативный | H22: UI | I22: Без сети показана ошибка создания, ложного сообщения об успехе нет. После восстановления создаётся ровно один РОП, введённые данные не превращаются в дубликаты. | K22: Not Run | L22: —

Sheet 04 Лиды и статусы
A1: ID | B1: Краткое описание | C1: Полное описание | D1: Предусловия | E1: Шаги | F1: Приоритет | G1: Тип | H1: Способ проверки | I1: Ожидаемый результат | J1: Фактический результат | K1: Статус | L1: Автоматизация
A2: TC-065 | B2: Таблица рабочих лидов показывает статус и историю попыток | C2: Рабочий лид — это сделка из AmoCRM, а не заявка с лендинга в меню супер-админа. Проверяем основные данные, по которым оператор понимает, кому уже звонили. | D2: Выполнен вход под оператором. Ему назначена тестовая воронка; в ней есть лид, по которому уже выполнялся звонок через Operator AI. | E2: 1. В меню открой «Звонки». 2. Найди тестовый лид по названию сделки. 3. Сверь колонки «Название сделки», «Статус», «Попытки», «Последний звонок» и «Действие». 4. Нажми на строку лида. 5. Проверь блок «Данные сделки» и список связанных звонков. | F2: High | G2: Позитивный | H2: UI | I2: В строке показаны актуальный узбекский статус, число попыток и время последнего звонка. Карточка относится к тому же лиду; данные чужих воронок не показаны. | K2: Not Run | L2: —
A3: TC-066 | B3: Все варианты апострофа распознаются как Ko'tarmadi | C3: Название «Ko'tarmadi» означает «не поднял трубку». Система удаляет разные виды апострофа, поэтому одинаковый смысл не должен зависеть от раскладки клавиатуры. | D3: В тестовой воронке созданы статусы `Ko'tarmadi`, `Ko’tarmadi`, `Koʻtarmadi`, `Koʼtarmadi` и `Kotarmadi`; в каждом — по одному тестовому лиду без прошлых попыток. Других доступных лидов у оператора нет. | E3: 1. Войди под оператором после начала рабочего дня. 2. Открой «Обзвон» и нажми «Начать обзвон». 3. Для каждого выданного лида сразу нажимай «Пауза», затем «Пропустить», чтобы не звонить. 4. Повторяй, пока проверишь все пять лидов. | F3: High | G3: Граничный | H3: UI | I3: Все пять лидов попадают в очередь как один класс «Не поднял трубку». Ни один вариант апострофа не пропадает. | K3: Not Run | L3: —
A4: TC-067 | B4: Статус со словом Chala попадает в очередь | C4: Слово `chala` означает незавершённый разговор. Статус может содержать дополнительные слова, но система должна узнать его по ключевому слову. | D4: В назначенной оператору тестовой воронке есть единственный лид в статусе «Chala gaplashdi — qayta aloqa», прошлых звонков у лида нет. | E4: 1. Войди под оператором и открой «Обзвон». 2. Нажми «Начать обзвон». 3. До окончания таймера нажми «Пауза». 4. Сверь название выданного лида и нажми «Пропустить». | F4: High | G4: Позитивный | H4: UI | I4: Выдан именно подготовленный лид. Система распознала слово `Chala` внутри более длинного названия. | K4: Not Run | L4: —
A5: TC-068 | B5: Keyingi qo'ng'iroq требует оба слова и наступившее время | C5: Статус повторного звонка распознаётся только при наличии обоих слов `keyingi` и `qongiroq`; лид доступен, когда согласованное время уже наступило. | D5: Есть один лид со статусом «Keyingi qo'ng'iroq vaqti» и временем следующего звонка на 5 минут раньше текущего. Других лидов в очереди нет. | E5: 1. Открой «Обзвон» под назначенным оператором. 2. Проверь число лидов в очереди. 3. Нажми «Начать обзвон», сразу нажми «Пауза». 4. Сверь название лида и нажми «Пропустить». | F5: Critical | G5: Позитивный | H5: UI | I5: Лид присутствует в очереди и выдаётся оператору, потому что оба ключевых слова есть, а время звонка уже наступило. | K5: Not Run | L5: —
A6: TC-069 | B6: Keyingi qo'ng'iroq без времени не выдаётся | C6: Негативный сценарий: одного названия статуса недостаточно. Без конкретного времени система не знает, когда звонить, поэтому такой лид молча выпадает из очереди. | D6: В тестовой воронке есть единственный лид в статусе «Keyingi qo'ng'iroq vaqti», поле следующего звонка пустое. | E6: 1. Войди под назначенным оператором. 2. Открой раздел «Обзвон». 3. Посмотри счётчик «лидов в очереди». 4. Нажми «Начать обзвон». | F6: Critical | G6: Негативный | H6: UI | I6: Счётчик равен нулю, подготовленный лид не выдаётся. Показано сообщение «Очередь пуста», а звонок не начинается. | K6: Not Run | L6: —
A7: TC-070 | B7: Bugun keladi без времени прихода доступен с начала дня | C7: Если клиент обещал прийти сегодня, но час не указан, очередь использует параметр «Начало рабочего дня» (по умолчанию 08:00 по Ташкенту). | D7: Проверка выполняется после времени «Начало рабочего дня». Есть единственный лид в статусе «Bugun keladi», поле `call vaqti` пустое. | E7: 1. Войди под назначенным оператором после начала рабочего дня. 2. Открой «Обзвон» и нажми «Начать обзвон». 3. Сразу нажми «Пауза» и сверь название лида. 4. Нажми «Пропустить». | F7: High | G7: Позитивный | H7: UI | I7: Лид выдан оператору. Пустое время прихода не блокирует его после начала рабочего дня. | K7: Not Run | L7: —
A8: TC-071 | B8: Bugun keladi появляется ровно за заданное время до прихода | C8: Проверяем границу параметра «Время звонка перед приходом». При значении 60 минут лид не должен появиться раньше, но должен стать доступен на границе. | D8: Параметр равен 60 минут. Есть лид «Bugun keladi» с полем `call vaqti` на сегодня. Тестировщик может менять тестовое время прихода. | E8: 1. Установи время прихода на 61 минуту позже текущего и обнови «Обзвон». 2. Проверь, что лида нет в очереди. 3. Измени время прихода на 60 минут позже текущего и дождись синхронизации. 4. Обнови «Обзвон» и нажми «Начать обзвон». 5. Поставь таймер на паузу и сверь лида. | F8: Critical | G8: Граничный | H8: UI | I8: За 61 минуту лид ещё не выдаётся. На границе 60 минут он появляется и может быть взят в работу. | K8: Not Run | L8: —
A9: TC-072 | B9: Uchrashuv до дня встречи не попадает в обзвон | C9: Статус `Uchrashuv` означает, что встреча назначена на будущий день. Звонить сейчас не нужно, поэтому этот класс находится вне очереди. | D9: Есть единственный лид в статусе «Uchrashuv vaqti» с датой встречи завтра. | E9: 1. Войди под назначенным оператором. 2. Открой «Обзвон». 3. Проверь число лидов и нажми «Начать обзвон». | F9: High | G9: Негативный | H9: UI | I9: Подготовленный лид не выдаётся; очередь пуста. | K9: Not Run | L9: —
A10: TC-073 | B10: Markazga keldi не попадает в обзвон | C10: Статус означает, что клиент уже пришёл в центр. Автоматически звонить ему больше не нужно. | D10: Есть единственный лид в статусе «Markazga keldi». | E10: 1. Открой «Обзвон» под назначенным оператором. 2. Проверь счётчик очереди. 3. Нажми «Начать обзвон». | F10: High | G10: Позитивный | H10: UI | I10: Лид не находится в очереди и не выдаётся оператору. | K10: Not Run | L10: —
A11: TC-074 | B11: Sifatsiz не возвращается в обзвон | C11: Sifatsiz — официально отбракованный лид. После такого статуса система не должна снова звонить клиенту. | D11: Есть единственный лид в статусе «Sifatsiz», блокировок и будущего времени звонка нет. | E11: 1. Войди под оператором и открой «Обзвон». 2. Проверь число лидов в очереди. 3. Нажми «Начать обзвон». | F11: Critical | G11: Позитивный | H11: UI | I11: Лид не выдаётся ни при каких временных настройках; очередь пуста. | K11: Not Run | L11: —
A12: TC-075 | B12: Yangi lid доступен сразу | C12: Новый лид имеет самый низкий приоритет, но при отсутствии более срочных лидов должен попасть оператору без задержки. | D12: Есть единственный новый лид в статусе «Yangi lid», воронка назначена оператору. | E12: 1. Открой «Обзвон». 2. Нажми «Начать обзвон». 3. Сразу нажми «Пауза». 4. Сверь название лида и нажми «Пропустить». | F12: Critical | G12: Позитивный | H12: UI | I12: Новый лид сразу отображается в очереди и выдаётся оператору. | K12: Not Run | L12: —
A13: TC-076 | B13: Неизвестный или пустой статус безопасно исключается | C13: Если название не содержит известного ключевого слова, система выбирает безопасный вариант: не звонит автоматически по непонятному этапу. | D13: Есть два тестовых лида: один со статусом «Ожидает документов», второй без связанного локального статуса. Других лидов у оператора нет. | E13: 1. Дождись синхронизации лидов. 2. Открой «Обзвон» под назначенным оператором. 3. Проверь счётчик и нажми «Начать обзвон». | F13: High | G13: Негативный | H13: UI | I13: Оба лида исключены из очереди. Нет случайного звонка и внутренней ошибки. | K13: Not Run | L13: —
... A28: TC-091 | B28: Список лидов восстанавливается после потери сети | C28: Проверяем отрицательный сценарий: временная потеря интернета не должна показывать устаревшие данные как свежие или ломать страницу навсегда. | D28: Под оператором открыт раздел «Звонки», тестовый лид виден в таблице. | E28: 1. В инструментах браузера включи Offline. 2. Обнови страницу или дождись очередного обновления данных. 3. Проверь сообщение на экране. 4. В AmoCRM измени статус тестового лида. 5. Верни сеть в режим Online. 6. Дождись автоматического переподключения либо обнови страницу один раз. | F28: High | G28: Негативный | H28: UI | I28: Без сети показана понятная ошибка «Не удалось загрузить сделки», страница не падает. После восстановления соединения список снова загружается и показывает актуальный статус без дубликатов. | K28: Not Run | L28: —

Sheet 05 Очередь обзвона
A1: ID | B1: Краткое описание | C1: Полное описание | D1: Предусловия | E1: Шаги | F1: Приоритет | G1: Тип | H1: Способ проверки | I1: Ожидаемый результат | J1: Фактический результат | K1: Статус | L1: Автоматизация
A2: TC-092 | B2: Счётчик показывает только доступные лиды оператора | C2: Проверяем число над подписью «лидов в очереди». В него должны входить только лиды из назначенных оператору воронок, у которых уже наступило время звонка. Закрытые, удалённые, отложенные и занятые другим оператором лиды не считаются. | D2: Для оператора подготовлена отдельная тестовая воронка. В ней ровно 3 доступных лида и по одному закрытому, удалённому и отложенному лиду. Другие операторы тестовую воронку сейчас не обзванивают. | E2: 1. Войди под тестовым оператором. 2. В левом меню открой «Режим звонков» — экран с заголовком «Обзвон». 3. Посмотри число над подписью «лидов в очереди». 4. Сверь имена трёх доступных лидов с подготовленным списком. | F2: High | G2: Позитивный | H2: UI | I2: Счётчик равен 3. Закрытый, удалённый, отложенный и недоступный оператору лиды в это число не входят. | K2: Not Run | L2: —
A3: TC-093 | B3: Счётчик очереди обновляется каждые 30 секунд | C3: Экран «Обзвон» сам обновляет число лидов раз в 30 секунд, пока окно обзвона закрыто. Проверяем, что новый лид появляется без перезагрузки страницы. | D3: Под оператором открыт экран «Обзвон». РОП может добавить тестовый лид в назначенную этому оператору воронку. Окно с инструкцией перед звонком закрыто. | E3: 1. Запиши текущее число «лидов в очереди». 2. В AmoCRM создай доступный сейчас тестовый лид со статусом «Yangi lid». 3. Не обновляй страницу Operator AI. 4. Подожди 35 секунд и снова посмотри на число. | F3: Medium | G3: Граничный | H3: UI | I3: Не позднее чем через 30–35 секунд счётчик увеличивается на 1. Страница не мигает и не создаёт дубликат лида. | K3: Not Run | L3: —
A4: TC-094 | B4: Очередь соблюдает порядок пяти классов | C4: Главное правило выбора следующего лида: сначала «Bugun keladi», затем «Keyingi qo'ng'iroq», «Chala gaplashdi», «Ko'tarmadi» и в конце «Yangi lid». Проверяем весь порядок на одном наборе данных. | D4: В одной назначенной оператору воронке подготовлено по одному доступному сейчас лиду каждого из пяти классов. Имена лидов начинаются с номера ожидаемого порядка: 1-Bugun, 2-Keyingi, 3-Chala, 4-Kotarmadi, 5-Yangi. | E4: 1. Войди под оператором и открой «Обзвон». 2. Нажми «Начать обзвон». 3. Запиши имя выданного лида и нажми «Пропустить». 4. Повтори предыдущий шаг, пока не увидишь все пять тестовых лидов. 5. Сравни записанный порядок с номерами в именах. | F4: Critical | G4: Позитивный | H4: UI | I4: Лиды выдаются строго так: 1-Bugun, 2-Keyingi, 3-Chala, 4-Kotarmadi, 5-Yangi. Пропущенный лид не появляется снова в этом же проходе. | K4: Not Run | L4: —
A5: TC-095 | B5: При равном приоритете раньше выдаётся более старый лид | C5: Если два лида относятся к одному классу, очередь выбирает того, чьё время звонка наступило раньше. Для двух новых лидов выбирается созданный раньше. | D5: В тестовой воронке нет других доступных лидов. Есть два лида одного класса: «QA-старый» стал доступен раньше, «QA-новый» — позже. | E5: 1. Открой «Обзвон» под назначенным оператором. 2. Нажми «Начать обзвон». 3. Сразу нажми «Пауза», чтобы звонок не начался. 4. Посмотри имя выданного лида. | F5: High | G5: Граничный | H5: UI | I5: Первым выдан «QA-старый». Порядок не меняется после обновления страницы. | K5: Not Run | L5: —
A6: TC-096 | B6: Будущее время звонка откладывает даже приоритетный лид | C6: Явно назначенное будущее время имеет силу для любого класса. Даже лид «Bugun keladi» не должен попасть в работу раньше этого времени. | D6: Есть два лида: «QA-Bugun-отложен» со статусом «Bugun keladi» и временем следующего звонка через 30 минут; «QA-Yangi-сейчас» доступен сейчас. Других лидов нет. | E6: 1. Открой «Обзвон» под оператором. 2. Нажми «Начать обзвон» и сразу «Пауза». 3. Посмотри имя лида. 4. Проверь счётчик очереди. | F6: Critical | G6: Негативный | H6: UI | I6: Выдан «QA-Yangi-сейчас». Отложенный приоритетный лид не выдан и не включён в текущий счётчик до наступления назначенного времени. | K6: Not Run | L6: —
A7: TC-097 | B7: Оператор получает лиды только назначенной воронки | C7: РОП связывает оператора с воронкой на экране «Настройка очереди». Лиды из невыбранной воронки не должны попадать этому оператору. | D7: У РОП есть две тестовые воронки A и B, в каждой по одному доступному лиду. Оператору назначена только воронка A. | E7: 1. Войди под РОП и открой «Настройка очереди». 2. В карточке оператора проверь: плашка воронки A синяя с галочкой, B — контурная с плюсом. 3. Выйди и войди под этим оператором. 4. Открой «Обзвон», нажми «Начать обзвон» и поставь таймер на паузу. 5. Проверь имя и воронку выданного лида. | F7: Critical | G7: Позитивный | H7: UI | I7: Оператор получает только лида из воронки A. Лид из B не входит в его счётчик и не выдаётся. | K7: Not Run | L7: —
A8: TC-098 | B8: Оператор работает с несколькими назначенными воронками | C8: Один оператор может быть связан сразу с несколькими воронками. Проверяем, что лиды обеих воронок участвуют в одной общей очереди по обычному приоритету. | D8: У РОП две тестовые воронки A и B. В A есть доступный «Yangi lid», в B — доступный «Bugun keladi». Оба назначения включены для одного оператора. | E8: 1. Под РОП открой «Настройка очереди» и убедись, что обе плашки воронок синие с галочкой. 2. Войди под оператором и открой «Обзвон». 3. Проверь, что счётчик включает оба лида. 4. Нажми «Начать обзвон» и сразу «Пауза». 5. Посмотри, из какой воронки пришёл первый лид. | F8: High | G8: Позитивный | H8: UI | I8: В счётчике 2 лида. Первым выдан «Bugun keladi» из воронки B, потому что приоритет класса важнее принадлежности к воронке. | K8: Not Run | L8: —
A9: TC-099 | B9: Снятие назначения сразу закрывает воронку оператору | C9: После снятия галочки в «Настройке очереди» новые лиды этой воронки больше не должны выдаваться оператору. | D9: Оператору назначена тестовая воронка с одним доступным лидом. У оператора нет незавершённой сессии обзвона. | E9: 1. Под РОП открой «Настройка очереди». 2. Нажми синюю плашку тестовой воронки в карточке оператора. 3. Дождись сообщения «Сохранено» и проверь, что плашка стала контурной с плюсом. 4. Войди под оператором и открой «Обзвон». 5. Проверь счётчик и нажми «Начать обзвон». | F9: Critical | G9: Негативный | H9: UI | I9: Лид снятой воронки не входит в счётчик и не выдаётся оператору. | K9: Not Run | L9: —
A10: TC-100 | B10: Два оператора одновременно получают разных лидов | C10: Проверка риска R-7: в общем пуле два оператора не должны начать звонить одному человеку. Проверку выполняют одновременно в двух окнах. | D10: Два активных оператора одного РОП назначены на одну воронку. В ней ровно два доступных лида. Открой два разных браузера или обычное и приватное окно. | E10: 1. В первом окне войди под оператором A, во втором — под оператором B. 2. В обоих окнах открой «Обзвон». 3. Попроси двух людей одновременно нажать «Начать обзвон»; если ты один, нажми кнопки быстро по очереди. 4. В обоих окнах сразу нажми «Пауза». 5. Сравни имена и телефоны выданных лидов. | F10: Critical | G10: Граничный | H10: UI | I10: Операторы получают двух разных лидов. Один и тот же телефон не показан одновременно в обоих окнах. | K10: Not Run | L10: —
A11: TC-101 | B11: Захваченный лид недоступен другому оператору пять минут | C11: После выдачи лид временно блокируется. Проверяем обычный срок блокировки до пяти минут, пока первый оператор готовится к звонку. | D11: Два оператора назначены на одну воронку. В очереди ровно один лид. | E11: 1. Под оператором A нажми «Начать обзвон» и сразу «Пауза». Не закрывай окно. 2. В течение следующих 4 минут под оператором B открой «Обзвон». 3. Посмотри счётчик и нажми «Начать обзвон». 4. Убедись, что оператор B не видит данные лида оператора A. | F11: Critical | G11: Негативный | H11: UI | I11: У оператора B счётчик не включает захваченный лид, и этот лид ему не выдаётся. | K11: Not Run | L11: —
A12: TC-102 | B12: Долгий звонок не допускает двойного обзвона после пяти минут | C12: Критическая проверка R-7. Блокировка в коде выдаётся на 5 минут. Если разговор длится дольше, второй оператор всё равно не должен получить этого же лида. Текущая реализация особенно рискованна для браузерного звонка. | D12: Два оператора назначены на одну воронку, где доступен только один лид. Клиентский тестовый номер может держать разговор дольше 6 минут. | E12: 1. Под оператором A начни звонок этому лиду и ответь на тестовом телефоне. 2. Не завершай разговор 6 минут. 3. После пятой минуты под оператором B открой «Обзвон» и нажми «Начать обзвон». 4. Сравни имя и телефон в окне B с лидом, которому уже звонит оператор A. | F12: Critical | G12: Граничный | H12: UI | I12: Оператор B НЕ получает занятого лида. Если тот же лид появился во втором окне, это критический дефект двойного обзвона R-7. | K12: Not Run | L12: —
A13: TC-103 | B13: Перезагрузка возвращает того же активного лида | C13: У одного оператора может быть только одна незавершённая сессия. Обновление страницы не должно брать новый лид или увеличивать число попыток. | D13: В очереди оператора минимум два лида. У первого лида известен текущий номер попытки. | E13: 1. Нажми «Начать обзвон» и сразу «Пауза». 2. Запиши имя лида и строку «Попытка», если она есть. 3. Обнови страницу браузера клавишей F5. 4. Снова открой «Обзвон» и нажми «Начать обзвон». 5. Сравни имя лида и номер попытки с записанными. | F13: Critical | G13: Негативный | H13: UI | I13: Возвращается тот же лид. Новый лид не захвачен, номер попытки не изменился. | K13: Not Run | L13: —
... A24: TC-114 | B24: Договорённость без часа использует заданное время | C24: Поле «Время звонка для договорённости без часа» должно дополнять фразу клиента вроде «позвоните в понедельник», когда конкретный час не назван. | D24: У РОП значение поля равно 10:15. Есть тестовая запись разговора, где клиент называет будущий день, но не называет час. Gemini на стенде доступен. | E24: 1. Проведи тестовый звонок и произнеси: «Позвоните мне в следующий понедельник». 2. Дождись экрана «Рекомендация ИИ — подтвердите». 3. Проверь поле «Время следующего звонка (для очереди)». 4. Подтверди результат. 5. Проверь сохранённое время следующего звонка. | F24: High | G24: Позитивный | H24: UI | I24: Дата соответствует следующему понедельнику по времени Ташкента, время — 10:15. Если поле пустое или указан другой час, настройка не подключена к расчёту. | K24: Not Run | L24: —

Sheet 06 Звонок (цикл)
A1: ID | B1: Краткое описание | C1: Полное описание | D1: Предусловия | E1: Шаги | F1: Приоритет | G1: Тип | H1: Способ проверки | I1: Ожидаемый результат | J1: Фактический результат | K1: Статус | L1: Автоматизация
A2: TC-115 | B2: Перед звонком показана понятная инструкция по лиду | C2: Проверяем первый экран цикла: оператор должен понять, кому и зачем звонит, какие статусы доступны и какие поля нужно узнать у клиента. | D2: У РОП настроены текст совета, форма с обязательным и необязательным полями и статусы. В очереди оператора есть тестовый лид с именем, телефоном, суммой и статусом. | E2: 1. Войди под оператором, открой «Обзвон» и нажми «Начать обзвон». 2. Сразу нажми «Пауза». 3. Сверь имя, телефон, текущий статус и сумму с тестовым лидом. 4. Прочитай блоки «Причина звонка», «Совет ИИ», «Целевые статусы» и «Поля, заполняемые ИИ». 5. Проверь, что обязательные поля отмечены маленькой цветной точкой. | F2: High | G2: Позитивный | H2: UI | I2: Данные относятся к выданному лиду. Совет совпадает с настройкой РОП. Показаны реальные статусы воронки и реальные поля формы; обязательные поля отмечены. | K2: Not Run | L2: —
A3: TC-116 | B3: Первый контакт не показывает попытку 0/4 | C3: Для лида, которому ещё не звонили, блок «Причина звонка» должен говорить о первом обращении, а не показывать непонятный нулевой счётчик. | D3: В очереди есть новый лид без прошлых звонков, времени последней попытки и предыдущего статуса. | E3: 1. Открой инструкцию этого лида и нажми «Пауза». 2. Найди блок «Причина звонка». 3. Прочитай главный текст и строки под ним. | F3: Medium | G3: Граничный | H3: UI | I3: Показан текст «Новый лид — вы связываетесь впервые…». Нет строк «Попытка 0/4», «Прошлый этап» с пустым значением или неверного времени. | K3: Not Run | L3: —
A4: TC-117 | B4: Повторный звонок показывает номер попытки и прошлый этап | C4: Оператору нужен контекст повторного обращения. Проверяем номер попытки, предыдущий этап, последнее время звонка и время встречи или прихода. | D4: Есть лид «Ko'tarmadi» с двумя завершёнными попытками из четырёх, известным предыдущим статусом и заполненным временем встречи либо прихода. | E4: 1. Открой инструкцию этого лида и нажми «Пауза». 2. В блоке «Причина звонка» найди строки «Попытка», «Прошлый этап» и «Последняя попытка». 3. Если подготовлено время встречи/прихода, найди соответствующую строку. 4. Сверь каждое значение с карточкой и историей тестового лида. | F4: High | G4: Позитивный | H4: UI | I4: Показано «Попытка 2/4», правильный прошлый этап и правильные дата/время. Значения не перепутаны между лидами. | K4: Not Run | L4: —
A5: TC-118 | B5: Последняя попытка выделена как важная | C5: Перед последним разрешённым недозвоном блок причины окрашивается в янтарный цвет, чтобы предупредить оператора о возможном переводе в «Sifatsiz». | D5: Максимум попыток равен 4. Есть лид «Ko'tarmadi» с тремя уже записанными попытками. | E5: 1. Открой инструкцию этого лида и нажми «Пауза». 2. Проверь строку «Попытка». 3. Сравни цвет левой полосы и заголовка блока «Причина звонка» с обычным повторным лидом. | F5: Medium | G5: Граничный | H5: UI | I5: Показано «Попытка 3/4», а блок выделен янтарным цветом. Инструкция и кнопки остаются читаемыми. | K5: Not Run | L5: —
A6: TC-119 | B6: Неполные данные причины не ломают инструкцию | C6: Блок причины собирается из доступных данных. Если прошлый статус или время встречи отсутствует, экран должен просто скрыть пустые строки. | D6: Есть доступный лид без предыдущего статуса, времени встречи, времени прихода и истории попыток. Имя или сумма также могут быть пустыми. | E6: 1. Открой инструкцию этого лида и нажми «Пауза». 2. Просмотри блок «Причина звонка» и верхнюю строку окна. 3. Нажми «Продолжить», затем снова «Пауза». | F6: High | G6: Негативный | H6: UI | I6: Окно открывается без белого экрана и технической ошибки. Пустые строки не показываются; для пустого имени используется «Лид без имени». Таймер и кнопки работают. | K6: Not Run | L6: —
A7: TC-120 | B7: В итогах доступны только статусы воронки лида | C7: Статус результата нельзя взять из чужой воронки или из системных этапов. Если РОП не настроил список формы, система должна подставить живые статусы AmoCRM этой воронки. | D7: У РОП две воронки с разными статусами. Для теста поочерёдно подготовлены два состояния: форма со статусами и форма без них. Есть лид в воронке A. | E7: 1. Проведи тестовый звонок до экрана «Итог разговора — подтвердите». 2. Раскрой поле «Статус» и запиши варианты. 3. Проверь, что нет статусов воронки B, «Неразобранное», системных 142/143, «Yangi» и «Sifatsiz». 4. Повтори проверку после удаления настроенных статусов формы у РОП. | F7: Critical | G7: Негативный | H7: UI | I7: В обоих состояниях список не пуст и содержит только допустимые живые статусы воронки A. Чужие и системные этапы выбрать нельзя. | K7: Not Run | L7: —
A8: TC-121 | B8: Через 10 секунд номер набирается автоматически | C8: После показа инструкции кольцевой таймер идёт от 10 до 0 и сам начинает звонок, если оператор ничего не нажал. | D8: Телефония тестового оператора готова. Есть доступный лид с тестовым номером. | E8: 1. Нажми «Начать обзвон». 2. Не нажимай кнопки и наблюдай число в кольце. 3. Засеки время от появления 10 до начала набора. 4. Проверь состояние в верхней строке окна. | F8: High | G8: Граничный | H8: UI | I8: Число уменьшается раз в секунду. Примерно через 10 секунд начинается один звонок, верхняя строка меняется на «В ЭФИРЕ». | K8: Not Run | L8: —
A9: TC-122 | B9: «Пауза» останавливает таймер, «Продолжить» возобновляет | C9: Проверяем, что пауза действительно замораживает отсчёт, а не только меняет надпись. | D9: Открыта инструкция перед звонком, автоматический набор ещё не начался. | E9: 1. Когда на кольце будет 7 или 8, нажми «Пауза». 2. Запиши число и подожди 5 секунд. 3. Убедись, что кнопка теперь называется «Продолжить». 4. Нажми «Продолжить» и наблюдай таймер. | F9: High | G9: Позитивный | H9: UI | I9: Во время паузы число не меняется и звонок не начинается. После «Продолжить» отсчёт продолжается с сохранённого числа, а не начинается заново. | K9: Not Run | L9: —
A10: TC-123 | B10: «Позвонить сейчас» начинает только один звонок | C10: Оператор может не ждать таймер. Быстрое повторное нажатие не должно создать два исходящих звонка одному клиенту. | D10: Открыта инструкция, телефония готова, тестовый телефон находится у тестировщика. | E10: 1. Очень быстро дважды нажми «Позвонить сейчас». 2. Посмотри экран Operator AI и журнал входящих на тестовом телефоне. 3. Ответь на вызов и затем заверши его. | F10: Critical | G10: Негативный | H10: UI | I10: Начинается ровно один вызов. Открыт один экран разговора; на телефоне нет двух параллельных или последовательных дублей от двойного клика. | K10: Not Run | L10: —
